Workbook

Sheet Executive Summary
A1: Senior Revenue Operations Analyst Assessment — Executive Briefing
A3: Reporting Period: FY 2025 (Dec-24 Opening Snapshot to Dec-25 Closing Snapshot)
A4: Deliverables Covered: Part 1 (ARR Snowball & Product Mix) & Part 2 (GTM Funnel vs Plan)
A6: Part 1: ARR Snowball Dynamics & Product Mix Evolution
A8: 1. Topline Portfolio Expansion (+91.7% YoY):
A10: Annual Recurring Revenue (ARR) grew from $1,926,000 (Dec-24) to $3,692,000 (Dec-25), delivering +$1,766,000 in Net New ARR.
A11: Growth was well-balanced between aggressive new logo acquisition ($1,255,000 in New ARR across 15 new accounts) and existing customer upsell/cross-sell ($791,000 in Expansion ARR).
A12: 2. Product Mix Shift Toward High-Velocity Add-Ons:
A14: Core Platform remains the foundation of the business, expanding from $1.56M to $2.65M (+69.5%), but its portfolio share contracted from 81.2% to 71.7% as add-ons outpaced core growth.
A15: Automation demonstrated exceptional product-market fit: ARR grew 4.6x from $83,000 to $384,000 (+362.7%), expanding its portfolio share from 4.3% to 10.4%.
A16: Analytics more than doubled: ARR expanded from $280,000 to $659,000 (+135.4%), climbing from 14.5% to 17.8% of the book.
A17: 3. Retention Framing & Quarterly Churn Rhythm:
... A48: Executive KPI Summary Card
A50: Core RevOps Metric | B50: Dec-2024 (Start) | C50: Dec-2025 (End) | D50: FY 2025 Performance
A51: Total Active ARR | B51: 1926000 | C51: 3692000 | D51: +$1,766,000 (+91.7%)
A52: New Logo ARR | B52: — | C52: — | D52: $1,255,000 (15 new accounts)
A53: Expansion ARR | B53: — | C53: — | D53: $791,000 (existing accounts)
A54: Total Churn ARR | B54: — | C54: — | D54: ($237,000) (3 quarterly accounts)
A55: New Bookings ARR Plan Attainment | B55: — | C55: — | D55: 101.5% ($2.67M vs $2.63M plan)
A56: SQL Plan Attainment | B56: — | C56: — | D56: 103.3% (442 vs 428 plan)
A57: Core Platform Mix % | B57: 0.812 | C57: 0.717 | D57: -9.5 pts (share ceded to add-ons)
A58: Analytics Mix % | B58: 0.145 | C58: 0.178 | D58: +3.3 pts (+$379k ARR)
A59: Automation Mix % | B59: 0.043 | C59: 0.104 | D59: +6.1 pts (+4.6x ARR growth)
A60: Cohort Annual NRR | B60: — | C60: — | D60: 1.263
A61: Snowball Math Status | B61: — | C61: — | D61: 100% TIED across all 12 months

Sheet ARR Snowball
A1: ARR Metric (in USD) | B1: Jan-25 | C1: Feb-25 | D1: Mar-25 | E1: Apr-25 | F1: May-25 | G1: Jun-25 | H1: Jul-25 | I1: Aug-25 | J1: Sep-25 | K1: Oct-25 | L1: Nov-25 | M1: Dec-25
A2: Starting ARR | B2: ='Customer ARR Matrix'!C39 -> 1926000 | C2: =B7 -> 2158000 | D2: =C7 -> 2296000 | E2: =D7 -> 2522000 | F2: =E7 -> 2600000 | G2: =F7 -> 2797000 | H2: =G7 -> 2966000 | I2: =H7 -> 3053000 | J2: =I7 -> 3172000 | ... M2: =L7 -> 3558000 | N2: =+B2 -> 1926000
A3: (+) New ARR | B3: ='Customer ARR Matrix'!D41 -> 177000 | C3: ='Customer ARR Matrix'!E41 -> 66000 | D3: ='Customer ARR Matrix'!F41 -> 156000 | E3: ='Customer ARR Matrix'!G41 -> 105000 | F3: ='Customer ARR Matrix'!H41 -> 103000 | G3: ='Customer ARR Matrix'!I41 -> 125000 | H3: ='Customer ARR Matrix'!J41 -> 114000 | I3: ='Customer ARR Matrix'!K41 -> 44000 | ... M3: ='Customer ARR Matrix'!O41 -> 88000 | N3: =SUM(B3:M3) -> 1255000
A4: (+) Expansion ARR | B4: ='Customer ARR Matrix'!D42 -> 55000 | C4: ='Customer ARR Matrix'!E42 -> 72000 | D4: ='Customer ARR Matrix'!F42 -> 70000 | E4: ='Customer ARR Matrix'!G42 -> 60000 | F4: ='Customer ARR Matrix'!H42 -> 94000 | G4: ='Customer ARR Matrix'!I42 -> 60000 | H4: ='Customer ARR Matrix'!J42 -> 50000 | I4: ='Customer ARR Matrix'!K42 -> 75000 | ... M4: ='Customer ARR Matrix'!O42 -> 46000 | N4: =SUM(B4:M4) -> 791000
A5: (-) Contraction ARR | B5: ='Customer ARR Matrix'!D43 -> 0 | C5: ='Customer ARR Matrix'!E43 -> 0 | D5: ='Customer ARR Matrix'!F43 -> 0 | E5: ='Customer ARR Matrix'!G43 -> 0 | F5: ='Customer ARR Matrix'!H43 -> 0 | G5: ='Customer ARR Matrix'!I43 -> 16000 | H5: ='Customer ARR Matrix'!J43 -> 0 | I5: ='Customer ARR Matrix'!K43 -> 0 | ... M5: ='Customer ARR Matrix'!O43 -> 0 | N5: =SUM(B5:M5) -> 43000
A6: (-) Churn ARR | B6: ='Customer ARR Matrix'!D44 -> 0 | C6: ='Customer ARR Matrix'!E44 -> 0 | D6: ='Customer ARR Matrix'!F44 -> 0 | E6: ='Customer ARR Matrix'!G44 -> 87000 | F6: ='Customer ARR Matrix'!H44 -> 0 | G6: ='Customer ARR Matrix'!I44 -> 0 | H6: ='Customer ARR Matrix'!J44 -> 77000 | I6: ='Customer ARR Matrix'!K44 -> 0 | ... M6: ='Customer ARR Matrix'!O44 -> 0 | N6: =SUM(B6:M6) -> 237000
A7: Ending ARR | B7: ='Customer ARR Matrix'!D39 -> 2158000 | C7: ='Customer ARR Matrix'!E39 -> 2296000 | D7: ='Customer ARR Matrix'!F39 -> 2522000 | E7: ='Customer ARR Matrix'!G39 -> 2600000 | F7: ='Customer ARR Matrix'!H39 -> 2797000 | G7: ='Customer ARR Matrix'!I39 -> 2966000 | H7: ='Customer ARR Matrix'!J39 -> 3053000 | I7: ='Customer ARR Matrix'!K39 -> 3172000 | ... M7: ='Customer ARR Matrix'!O39 -> 3692000 | N7: =M7 -> 3692000
A8: Net New ARR | B8: =B7 - B2 -> 232000 | C8: =C7 - C2 -> 138000 | D8: =D7 - D2 -> 226000 | E8: =E7 - E2 -> 78000 | F8: =F7 - F2 -> 197000 | G8: =G7 - G2 -> 169000 | H8: =H7 - H2 -> 87000 | I8: =I7 - I2 -> 119000 | ... N8: =N7 - N2 -> 1766000
A9: Tie Check | B9: =IF(B7 = (B2 + B3 + B4 - B5 - B6), "TIED", "MISMATCH") -> TIED | C9: =IF(C7 = (C2 + C3 + C4 - C5 - C6), "TIED", "MISMATCH") -> TIED | D9: =IF(D7 = (D2 + D3 + D4 - D5 - D6), "TIED", "MISMATCH") -> TIED | E9: =IF(E7 = (E2 + E3 + E4 - E5 - E6), "TIED", "MISMATCH") -> TIED | F9: =IF(F7 = (F2 + F3 + F4 - F5 - F6), "TIED", "MISMATCH") -> TIED | G9: =IF(G7 = (G2 + G3 + G4 - G5 - G6), "TIED", "MISMATCH") -> TIED | H9: =IF(H7 = (H2 + H3 + H4 - H5 - H6), "TIED", "MISMATCH") -> TIED | I9: =IF(I7 = (I2 + I3 + I4 - I5 - I6), "TIED", "MISMATCH") -> TIED | ... N9: =IF(N7 = (N2 + N3 + N4 - N5 - N6), "TIED", "MISMATCH") -> TIED
A10: Monthly NRR % | B10: =(B2 + B4 - B5 - B6) / B2 -> 1.0285566 | C10: =(C2 + C4 - C5 - C6) / C2 -> 1.0333642 | D10: =(D2 + D4 - D5 - D6) / D2 -> 1.0304878 | E10: =(E2 + E4 - E5 - E6) / E2 -> 0.98929421 | F10: =(F2 + F4 - F5 - F6) / F2 -> 1.0361538 | G10: =(G2 + G4 - G5 - G6) / G2 -> 1.0157311 | H10: =(H2 + H4 - H5 - H6) / H2 -> 0.99089683 | I10: =(I2 + I4 - I5 - I6) / I2 -> 1.024566 | ... N10: =(N2 + N4 - N5 - N6) / N2 -> 1.2653167
A11: Monthly GRR % | B11: =(B2 - B5 - B6) / B2 -> 1 | C11: =(C2 - C5 - C6) / C2 -> 1 | D11: =(D2 - D5 - D6) / D2 -> 1 | E11: =(E2 - E5 - E6) / E2 -> 0.96550357 | F11: =(F2 - F5 - F6) / F2 -> 1 | G11: =(G2 - G5 - G6) / G2 -> 0.99427959 | H11: =(H2 - H5 - H6) / H2 -> 0.97403911 | I11: =(I2 - I5 - I6) / I2 -> 1 | ... N11: =(N2 - N5 - N6) / N2 -> 0.85462098

Sheet ARR by Product
A1: Suma de ARR_USD | B1: Etiquetas de columna
A2: Etiquetas de fila | B2: 45627 | C2: 45658 | D2: 45689 | E2: 45717 | F2: 45748 | G2: 45778 | H2: 45809 | I2: 45839 | J2: 45870 | K2: 45901 | L2: 45931 | M2: 45962 | N2: 45992 | O2: Total general
A3: Analytics | B3: 280000 | C3: 309000 | D3: 309000 | E3: 361000 | F3: 407000 | G3: 437000 | H3: 481000 | I3: 494000 | J3: 521000 | K3: 562000 | L3: 609000 | M3: 634000 | N3: 659000 | O3: 6063000
A4: Automation | B4: 83000 | C4: 139000 | D4: 169000 | E4: 169000 | F4: 175000 | G4: 192000 | H4: 231000 | I4: 277000 | J4: 287000 | K4: 306000 | L4: 325000 | M4: 363000 | N4: 384000 | O4: 3100000
A5: Core Platform | B5: 1563000 | C5: 1710000 | D5: 1818000 | E5: 1992000 | F5: 2018000 | G5: 2168000 | H5: 2254000 | I5: 2282000 | J5: 2364000 | K5: 2467000 | L5: 2494000 | M5: 2561000 | N5: 2649000 | O5: 28340000
A6: Total general | B6: 1926000 | C6: 2158000 | D6: 2296000 | E6: 2522000 | F6: 2600000 | G6: 2797000 | H6: 2966000 | I6: 3053000 | J6: 3172000 | K6: 3335000 | L6: 3428000 | M6: 3558000 | N6: 3692000 | O6: 37503000
A8: Product Mix (% of Total ARR) | B8: =B2 -> 45627 | C8: =C2 -> 45658 | D8: =D2 -> 45689 | E8: =E2 -> 45717 | F8: =F2 -> 45748 | G8: =G2 -> 45778 | H8: =H2 -> 45809 | I8: =I2 -> 45839 | ... N8: =N2 -> 45992
A9: Core Platform % | B9: =B5 / B$6 -> 0.81152648 | C9: =C5 / C$6 -> 0.79240037 | D9: =D5 / D$6 -> 0.79181185 | E9: =E5 / E$6 -> 0.78984933 | F9: =F5 / F$6 -> 0.77615385 | G9: =G5 / G$6 -> 0.7751162 | H9: =H5 / H$6 -> 0.75994606 | I9: =I5 / I$6 -> 0.74746151 | ... N9: =N5 / N$6 -> 0.71749729
A10: Analytics % | B10: =B3 / B$6 -> 0.14537902 | C10: =C3 / C$6 -> 0.14318814 | D10: =D3 / D$6 -> 0.13458188 | E10: =E3 / E$6 -> 0.14314036 | F10: =F3 / F$6 -> 0.15653846 | G10: =G3 / G$6 -> 0.15623883 | H10: =H3 / H$6 -> 0.16217127 | I10: =I3 / I$6 -> 0.16180806 | ... N10: =N3 / N$6 -> 0.17849404
A11: Automation % | B11: =B4 / B$6 -> 0.043094496 | C11: =C4 / C$6 -> 0.064411492 | D11: =D4 / D$6 -> 0.073606272 | E11: =E4 / E$6 -> 0.067010309 | F11: =F4 / F$6 -> 0.067307692 | G11: =G4 / G$6 -> 0.068644977 | H11: =H4 / H$6 -> 0.07788267 | I11: =I4 / I$6 -> 0.090730429 | ... N11: =N4 / N$6 -> 0.10400867
A12: Total Mix | B12: =SUM(B9:B11) -> 1 | C12: =SUM(C9:C11) -> 1 | D12: =SUM(D9:D11) -> 1 | E12: =SUM(E9:E11) -> 1 | F12: =SUM(F9:F11) -> 1 | G12: =SUM(G9:G11) -> 1 | H12: =SUM(H9:H11) -> 1 | I12: =SUM(I9:I11) -> 1 | ... N12: =SUM(N9:N11) -> 1
A15: Executive Commentary — ARR Book Dynamics & Product Mix Evolution (FY 2025)
A17: 1. Portfolio Expansion:
A18: The ARR book expanded by +91.7% year-over-year from $1,926,000 to $3,692,000 (+$1,766,000 net new ARR), demonstrating balanced growth between new logo acquisition ($1,255,000 New ARR) and customer expansion ($791,000 Expansion ARR).
A19: 2. Mix Shift Toward High-Value Add-Ons:
A20: While Core Platform remains the revenue anchor ($2.65M), its share of total ARR decreased from 81.2% to 71.7%.
A21: Growth was heavily fueled by add-on cross-sells: Automation grew 4.6x ($83k to $384k), increasing its portfolio share from 4.3% to 10.4%, while Analytics more than doubled ($280k to $659k, reaching 17.8% of the book).
A22: 3. Retention & Churn Governance Flag:
A23: Retention was strong with a full-year cohort Net Revenue Retention (NRR) of 126.3% on the opening book.
A24: Key Leadership Flag: Churn of $237,000 occurred exclusively on the first month of quarterly renewal cycles (April: $87k, July: $77k, October: $73k). We recommend implementing a 90-day proactive Customer Success renewal cadence to mitigate recurring quarterly drop-offs.

Sheet Customer ARR Matrix
A1: Suma de ARR_USD | C1: Snapshot_Month
A2: Customer_ID | B2: Customer_Name_Cleaned | C2: 45627 | D2: 45658 | E2: 45689 | F2: 45717 | G2: 45748 | H2: 45778 | I2: 45809 | J2: 45839 | K2: 45870 | L2: 45901 | M2: 45931 | N2: 45962 | O2: 45992 | P2: Total general
A3: C001 | B3: Northwind Trading | C3: 144000 | D3: 144000 | E3: 144000 | F3: 144000 | G3: 144000 | H3: 144000 | I3: 144000 | J3: 166000 | K3: 166000 | L3: 166000 | M3: 166000 | N3: 166000 | O3: 166000 | P3: 2004000
A4: C002 | B4: Blue Harbor Logistics | C4: 47000 | D4: 47000 | E4: 58000 | F4: 58000 | G4: 58000 | H4: 72000 | I4: 72000 | J4: 72000 | K4: 82000 | L4: 82000 | M4: 82000 | N4: 107000 | O4: 107000 | P4: 944000
A5: C003 | B5: Vertex Manufacturing | C5: 85000 | D5: 94000 | E5: 94000 | F5: 94000 | G5: 94000 | H5: 94000 | I5: 94000 | J5: 94000 | K5: 121000 | L5: 121000 | M5: 121000 | N5: 121000 | O5: 121000 | P5: 1348000
A6: C004 | B6: Cedar Peak Utilities | C6: 86000 | D6: 86000 | E6: 86000 | F6: 87000 | G6: 0 | H6: 0 | I6: 0 | J6: 0 | K6: 0 | L6: 0 | M6: 0 | N6: 0 | O6: 0 | P6: 345000
A7: C005 | B7: Ridgeline HVAC | C7: 111000 | D7: 111000 | E7: 111000 | F7: 111000 | G7: 111000 | H7: 126000 | I7: 126000 | J7: 126000 | K7: 147000 | L7: 147000 | M7: 147000 | N7: 147000 | O7: 147000 | P7: 1668000
A8: C006 | B8: Sterling Facilities | C8: 120000 | D8: 120000 | E8: 120000 | F8: 120000 | G8: 120000 | H8: 155000 | I8: 155000 | J8: 155000 | K8: 155000 | L8: 155000 | M8: 155000 | N8: 155000 | O8: 155000 | P8: 1840000
A9: C007 | B9: Copperfield Electrical | C9: 62000 | D9: 62000 | E9: 62000 | F9: 62000 | G9: 62000 | H9: 62000 | I9: 46000 | J9: 46000 | K9: 46000 | L9: 36000 | M9: 36000 | N9: 36000 | O9: 36000 | P9: 654000
A10: C008 | B10: Meridian Water Group | C10: 85000 | D10: 85000 | E10: 104000 | F10: 128000 | G10: 128000 | H10: 128000 | I10: 128000 | J10: 128000 | K10: 140000 | L10: 140000 | M10: 140000 | N10: 140000 | O10: 140000 | P10: 1614000
A11: C009 | B11: Ironclad Security | C11: 98000 | D11: 98000 | E11: 98000 | F11: 98000 | G11: 129000 | H11: 129000 | I11: 129000 | J11: 136000 | K11: 136000 | L11: 145000 | M11: 145000 | N11: 145000 | O11: 147000 | P11: 1633000
A12: C010 | B12: Pinecrest Property | C12: 157000 | D12: 181000 | E12: 181000 | F12: 181000 | G12: 184000 | H12: 184000 | I12: 184000 | J12: 184000 | K12: 184000 | L12: 184000 | M12: 184000 | N12: 184000 | O12: 184000 | P12: 2356000
A13: C011 | B13: Summit Fire Protection | C13: 77000 | D13: 77000 | E13: 77000 | F13: 77000 | G13: 77000 | H13: 77000 | I13: 77000 | J13: 0 | K13: 0 | L13: 0 | M13: 0 | N13: 0 | O13: 0 | P13: 539000
A14: C012 | B14: Harborview Plumbing | C14: 115000 | D14: 115000 | E14: 115000 | F14: 115000 | G14: 119000 | H14: 119000 | I14: 119000 | J14: 119000 | K14: 119000 | L14: 119000 | M14: 119000 | N14: 119000 | O14: 119000 | P14: 1531000
... A38: C036 | B38: Pentland Ports | C38: 0 | D38: 0 | E38: 0 | F38: 0 | G38: 0 | H38: 0 | I38: 0 | J38: 0 | K38: 0 | L38: 0 | M38: 0 | N38: 0 | O38: 88000 | P38: 88000
A39: Total general | C39: 1926000 | D39: 2158000 | E39: 2296000 | F39: 2522000 | G39: 2600000 | H39: 2797000 | I39: 2966000 | J39: 3053000 | K39: 3172000 | L39: 3335000 | M39: 3428000 | N39: 3558000 | O39: 3692000 | P39: 37503000
A41: Monthly New ARR | D41: {=SUM(IF((C$3:C$38=0)*(D$3:D$38>0), D$3:D$38, 0))} -> 177000 | E41: {=SUM(IF((D$3:D$38=0)*(E$3:E$38>0), E$3:E$38, 0))} -> 66000 | F41: {=SUM(IF((E$3:E$38=0)*(F$3:F$38>0), F$3:F$38, 0))} -> 156000 | G41: {=SUM(IF((F$3:F$38=0)*(G$3:G$38>0), G$3:G$38, 0))} -> 105000 | H41: {=SUM(IF((G$3:G$38=0)*(H$3:H$38>0), H$3:H$38, 0))} -> 103000 | I41: {=SUM(IF((H$3:H$38=0)*(I$3:I$38>0), I$3:I$38, 0))} -> 125000 | J41: {=SUM(IF((I$3:I$38=0)*(J$3:J$38>0), J$3:J$38, 0))} -> 114000 | K41: {=SUM(IF((J$3:J$38=0)*(K$3:K$38>0), K$3:K$38, 0))} -> 44000 | ... P41: {=SUM(IF((O$3:O$38=0)*(P$3:P$38>0), P$3:P$38, 0))} -> 1614000
A42: Monthly Expansion ARR | D42: {=SUM(IF((C$3:C$38>0)*(D$3:D$38>C$3:C$38), D$3:D$38 - C$3:C$38, 0))} -> 55000 | E42: {=SUM(IF((D$3:D$38>0)*(E$3:E$38>D$3:D$38), E$3:E$38 - D$3:D$38, 0))} -> 72000 | F42: {=SUM(IF((E$3:E$38>0)*(F$3:F$38>E$3:E$38), F$3:F$38 - E$3:E$38, 0))} -> 70000 | G42: {=SUM(IF((F$3:F$38>0)*(G$3:G$38>F$3:F$38), G$3:G$38 - F$3:F$38, 0))} -> 60000 | H42: {=SUM(IF((G$3:G$38>0)*(H$3:H$38>G$3:G$38), H$3:H$38 - G$3:G$38, 0))} -> 94000 | I42: {=SUM(IF((H$3:H$38>0)*(I$3:I$38>H$3:H$38), I$3:I$38 - H$3:H$38, 0))} -> 60000 | J42: {=SUM(IF((I$3:I$38>0)*(J$3:J$38>I$3:I$38), J$3:J$38 - I$3:I$38, 0))} -> 50000 | K42: {=SUM(IF((J$3:J$38>0)*(K$3:K$38>J$3:J$38), K$3:K$38 - J$3:J$38, 0))} -> 75000 | ... P42: {=SUM(IF((O$3:O$38>0)*(P$3:P$38>O$3:O$38), P$3:P$38 - O$3:O$38, 0))} -> 32197000
A43: Monthly Contraction ARR | D43: {=SUM(IF((C$3:C$38>0)*(D$3:D$38<C$3:C$38)*(D$3:D$38>0), C$3:C$38 - D$3:D$38, 0))} -> 0 | E43: {=SUM(IF((D$3:D$38>0)*(E$3:E$38<D$3:D$38)*(E$3:E$38>0), D$3:D$38 - E$3:E$38, 0))} -> 0 | F43: {=SUM(IF((E$3:E$38>0)*(F$3:F$38<E$3:E$38)*(F$3:F$38>0), E$3:E$38 - F$3:F$38, 0))} -> 0 | G43: {=SUM(IF((F$3:F$38>0)*(G$3:G$38<F$3:F$38)*(G$3:G$38>0), F$3:F$38 - G$3:G$38, 0))} -> 0 | H43: {=SUM(IF((G$3:G$38>0)*(H$3:H$38<G$3:G$38)*(H$3:H$38>0), G$3:G$38 - H$3:H$38, 0))} -> 0 | I43: {=SUM(IF((H$3:H$38>0)*(I$3:I$38<H$3:H$38)*(I$3:I$38>0), H$3:H$38 - I$3:I$38, 0))} -> 16000 | J43: {=SUM(IF((I$3:I$38>0)*(J$3:J$38<I$3:I$38)*(J$3:J$38>0), I$3:I$38 - J$3:J$38, 0))} -> 0 | K43: {=SUM(IF((J$3:J$38>0)*(K$3:K$38<J$3:J$38)*(K$3:K$38>0), J$3:J$38 - K$3:K$38, 0))} -> 0 | ... P43: {=SUM(IF((O$3:O$38>0)*(P$3:P$38<O$3:O$38)*(P$3:P$38>0), O$3:O$38 - P$3:P$38, 0))} -> 0
A44: Monthly Churn ARR | D44: {=SUM(IF((C$3:C$38>0)*(D$3:D$38=0), C$3:C$38, 0))} -> 0 | E44: {=SUM(IF((D$3:D$38>0)*(E$3:E$38=0), D$3:D$38, 0))} -> 0 | F44: {=SUM(IF((E$3:E$38>0)*(F$3:F$38=0), E$3:E$38, 0))} -> 0 | G44: {=SUM(IF((F$3:F$38>0)*(G$3:G$38=0), F$3:F$38, 0))} -> 87000 | H44: {=SUM(IF((G$3:G$38>0)*(H$3:H$38=0), G$3:G$38, 0))} -> 0 | I44: {=SUM(IF((H$3:H$38>0)*(I$3:I$38=0), H$3:H$38, 0))} -> 0 | J44: {=SUM(IF((I$3:I$38>0)*(J$3:J$38=0), I$3:I$38, 0))} -> 77000 | K44: {=SUM(IF((J$3:J$38>0)*(K$3:K$38=0), J$3:J$38, 0))} -> 0 | ... P44: {=SUM(IF((O$3:O$38>0)*(P$3:P$38=0), O$3:O$38, 0))} -> 0

Sheet GTM Funnel
A1: Month | B1: {=INDEX(Clean_Funnel_Data!$A$2:$A$13, COLUMN()-1)} -> Jan-25 | C1: {=INDEX(Clean_Funnel_Data!$A$2:$A$13, COLUMN()-1)} -> Feb-25 | D1: {=INDEX(Clean_Funnel_Data!$A$2:$A$13, COLUMN()-1)} -> Mar-25 | E1: {=INDEX(Clean_Funnel_Data!$A$2:$A$13, COLUMN()-1)} -> Apr-25 | F1: {=INDEX(Clean_Funnel_Data!$A$2:$A$13, COLUMN()-1)} -> May-25 | G1: {=INDEX(Clean_Funnel_Data!$A$2:$A$13, COLUMN()-1)} -> Jun-25 | H1: {=INDEX(Clean_Funnel_Data!$A$2:$A$13, COLUMN()-1)} -> Jul-25 | I1: {=INDEX(Clean_Funnel_Data!$A$2:$A$13, COLUMN()-1)} -> Aug-25 | ... M1: {=INDEX(Clean_Funnel_Data!$A$2:$A$13, COLUMN()-1)} -> Dec-25 | N1: Total FY 2025
A2: MQL Attainment % | B2: {=INDEX(Clean_Funnel_Data!$C$2:$C$13, COLUMN()-1) / INDEX(Targets!$B$2:$B$13, COLUMN()-1)} -> 1.075 | C2: {=INDEX(Clean_Funnel_Data!$C$2:$C$13, COLUMN()-1) / INDEX(Targets!$B$2:$B$13, COLUMN()-1)} -> 1.047619 | D2: {=INDEX(Clean_Funnel_Data!$C$2:$C$13, COLUMN()-1) / INDEX(Targets!$B$2:$B$13, COLUMN()-1)} -> 0.93181818 | E2: {=INDEX(Clean_Funnel_Data!$C$2:$C$13, COLUMN()-1) / INDEX(Targets!$B$2:$B$13, COLUMN()-1)} -> 0.91304348 | F2: {=INDEX(Clean_Funnel_Data!$C$2:$C$13, COLUMN()-1) / INDEX(Targets!$B$2:$B$13, COLUMN()-1)} -> 0.95833333 | G2: {=INDEX(Clean_Funnel_Data!$C$2:$C$13, COLUMN()-1) / INDEX(Targets!$B$2:$B$13, COLUMN()-1)} -> 0.9 | H2: {=INDEX(Clean_Funnel_Data!$C$2:$C$13, COLUMN()-1) / INDEX(Targets!$B$2:$B$13, COLUMN()-1)} -> 0.94230769 | I2: {=INDEX(Clean_Funnel_Data!$C$2:$C$13, COLUMN()-1) / INDEX(Targets!$B$2:$B$13, COLUMN()-1)} -> 0.92592593 | ... M2: {=INDEX(Clean_Funnel_Data!$C$2:$C$13, COLUMN()-1) / INDEX(Targets!$B$2:$B$13, COLUMN()-1)} -> 1.0806452 | N2: =SUM(Clean_Funnel_Data!C2:C13) / SUM(Targets!B2:B13) -> 0.99346405
A3: SQL Attainment % | B3: {=INDEX(Clean_Funnel_Data!$D$2:$D$13, COLUMN()-1) / INDEX(Targets!$C$2:$C$13, COLUMN()-1)} -> 1.0357143 | C3: {=INDEX(Clean_Funnel_Data!$D$2:$D$13, COLUMN()-1) / INDEX(Targets!$C$2:$C$13, COLUMN()-1)} -> 1 | D3: {=INDEX(Clean_Funnel_Data!$D$2:$D$13, COLUMN()-1) / INDEX(Targets!$C$2:$C$13, COLUMN()-1)} -> 1.0322581 | E3: {=INDEX(Clean_Funnel_Data!$D$2:$D$13, COLUMN()-1) / INDEX(Targets!$C$2:$C$13, COLUMN()-1)} -> 1.125 | F3: {=INDEX(Clean_Funnel_Data!$D$2:$D$13, COLUMN()-1) / INDEX(Targets!$C$2:$C$13, COLUMN()-1)} -> 1.1176471 | G3: {=INDEX(Clean_Funnel_Data!$D$2:$D$13, COLUMN()-1) / INDEX(Targets!$C$2:$C$13, COLUMN()-1)} -> 1.0571429 | H3: {=INDEX(Clean_Funnel_Data!$D$2:$D$13, COLUMN()-1) / INDEX(Targets!$C$2:$C$13, COLUMN()-1)} -> 0.88888889 | I3: {=INDEX(Clean_Funnel_Data!$D$2:$D$13, COLUMN()-1) / INDEX(Targets!$C$2:$C$13, COLUMN()-1)} -> 1.1315789 | ... M3: {=INDEX(Clean_Funnel_Data!$D$2:$D$13, COLUMN()-1) / INDEX(Targets!$C$2:$C$13, COLUMN()-1)} -> 1.1162791 | N3: =SUM(Clean_Funnel_Data!D2:D13) / SUM(Targets!C2:C13) -> 1.0327103
A4: Opps Attainment % | B4: {=INDEX(Clean_Funnel_Data!$F$2:$F$13, COLUMN()-1) / INDEX(Targets!$D$2:$D$13, COLUMN()-1)} -> 1.1176471 | C4: {=INDEX(Clean_Funnel_Data!$F$2:$F$13, COLUMN()-1) / INDEX(Targets!$D$2:$D$13, COLUMN()-1)} -> 0.94444444 | D4: {=INDEX(Clean_Funnel_Data!$F$2:$F$13, COLUMN()-1) / INDEX(Targets!$D$2:$D$13, COLUMN()-1)} -> 1.1578947 | E4: {=INDEX(Clean_Funnel_Data!$F$2:$F$13, COLUMN()-1) / INDEX(Targets!$D$2:$D$13, COLUMN()-1)} -> 1.05 | F4: {=INDEX(Clean_Funnel_Data!$F$2:$F$13, COLUMN()-1) / INDEX(Targets!$D$2:$D$13, COLUMN()-1)} -> 0.85714286 | G4: {=INDEX(Clean_Funnel_Data!$F$2:$F$13, COLUMN()-1) / INDEX(Targets!$D$2:$D$13, COLUMN()-1)} -> 0.95454545 | H4: {=INDEX(Clean_Funnel_Data!$F$2:$F$13, COLUMN()-1) / INDEX(Targets!$D$2:$D$13, COLUMN()-1)} -> 0.90909091 | I4: {=INDEX(Clean_Funnel_Data!$F$2:$F$13, COLUMN()-1) / INDEX(Targets!$D$2:$D$13, COLUMN()-1)} -> 1 | ... M4: {=INDEX(Clean_Funnel_Data!$F$2:$F$13, COLUMN()-1) / INDEX(Targets!$D$2:$D$13, COLUMN()-1)} -> 0.88888889 | N4: =SUM(Clean_Funnel_Data!F2:F13) / SUM(Targets!D2:D13) -> 0.99622642
A5: Won Deals Attainment % | B5: {=INDEX(Clean_Funnel_Data!$G$2:$G$13, COLUMN()-1) / INDEX(Targets!$E$2:$E$13, COLUMN()-1)} -> 0.8 | C5: {=INDEX(Clean_Funnel_Data!$G$2:$G$13, COLUMN()-1) / INDEX(Targets!$E$2:$E$13, COLUMN()-1)} -> 1 | D5: {=INDEX(Clean_Funnel_Data!$G$2:$G$13, COLUMN()-1) / INDEX(Targets!$E$2:$E$13, COLUMN()-1)} -> 1.2 | E5: {=INDEX(Clean_Funnel_Data!$G$2:$G$13, COLUMN()-1) / INDEX(Targets!$E$2:$E$13, COLUMN()-1)} -> 0.83333333 | F5: {=INDEX(Clean_Funnel_Data!$G$2:$G$13, COLUMN()-1) / INDEX(Targets!$E$2:$E$13, COLUMN()-1)} -> 0.83333333 | G5: {=INDEX(Clean_Funnel_Data!$G$2:$G$13, COLUMN()-1) / INDEX(Targets!$E$2:$E$13, COLUMN()-1)} -> 1 | H5: {=INDEX(Clean_Funnel_Data!$G$2:$G$13, COLUMN()-1) / INDEX(Targets!$E$2:$E$13, COLUMN()-1)} -> 1.1666667 | I5: {=INDEX(Clean_Funnel_Data!$G$2:$G$13, COLUMN()-1) / INDEX(Targets!$E$2:$E$13, COLUMN()-1)} -> 0.85714286 | ... M5: {=INDEX(Clean_Funnel_Data!$G$2:$G$13, COLUMN()-1) / INDEX(Targets!$E$2:$E$13, COLUMN()-1)} -> 1 | N5: =SUM(Clean_Funnel_Data!G2:G13) / SUM(Targets!E2:E13) -> 0.98666667
A6: Bookings ARR Attainment % | B6: {=INDEX(Clean_Funnel_Data!$H$2:$H$13, COLUMN()-1) / INDEX(Targets!$F$2:$F$13, COLUMN()-1)} -> 0.91428571 | C6: {=INDEX(Clean_Funnel_Data!$H$2:$H$13, COLUMN()-1) / INDEX(Targets!$F$2:$F$13, COLUMN()-1)} -> 0.93714286 | D6: {=INDEX(Clean_Funnel_Data!$H$2:$H$13, COLUMN()-1) / INDEX(Targets!$F$2:$F$13, COLUMN()-1)} -> 1.1771429 | E6: {=INDEX(Clean_Funnel_Data!$H$2:$H$13, COLUMN()-1) / INDEX(Targets!$F$2:$F$13, COLUMN()-1)} -> 0.71428571 | F6: {=INDEX(Clean_Funnel_Data!$H$2:$H$13, COLUMN()-1) / INDEX(Targets!$F$2:$F$13, COLUMN()-1)} -> 1 | G6: {=INDEX(Clean_Funnel_Data!$H$2:$H$13, COLUMN()-1) / INDEX(Targets!$F$2:$F$13, COLUMN()-1)} -> 0.9047619 | H6: {=INDEX(Clean_Funnel_Data!$H$2:$H$13, COLUMN()-1) / INDEX(Targets!$F$2:$F$13, COLUMN()-1)} -> 1.2857143 | I6: {=INDEX(Clean_Funnel_Data!$H$2:$H$13, COLUMN()-1) / INDEX(Targets!$F$2:$F$13, COLUMN()-1)} -> 0.96326531 | ... M6: {=INDEX(Clean_Funnel_Data!$H$2:$H$13, COLUMN()-1) / INDEX(Targets!$F$2:$F$13, COLUMN()-1)} -> 1.0785714 | N6: =SUM(Clean_Funnel_Data!H2:H13) / SUM(Targets!F2:F13) -> 1.0152381
A7: Conv MQL → SQL | B7: {=INDEX(Clean_Funnel_Data!$D$2:$D$13, COLUMN()-1) / INDEX(Clean_Funnel_Data!$C$2:$C$13, COLUMN()-1)} -> 0.3372093 | C7: {=INDEX(Clean_Funnel_Data!$D$2:$D$13, COLUMN()-1) / INDEX(Clean_Funnel_Data!$C$2:$C$13, COLUMN()-1)} -> 0.32954545 | D7: {=INDEX(Clean_Funnel_Data!$D$2:$D$13, COLUMN()-1) / INDEX(Clean_Funnel_Data!$C$2:$C$13, COLUMN()-1)} -> 0.3902439 | E7: {=INDEX(Clean_Funnel_Data!$D$2:$D$13, COLUMN()-1) / INDEX(Clean_Funnel_Data!$C$2:$C$13, COLUMN()-1)} -> 0.42857143 | F7: {=INDEX(Clean_Funnel_Data!$D$2:$D$13, COLUMN()-1) / INDEX(Clean_Funnel_Data!$C$2:$C$13, COLUMN()-1)} -> 0.41304348 | G7: {=INDEX(Clean_Funnel_Data!$D$2:$D$13, COLUMN()-1) / INDEX(Clean_Funnel_Data!$C$2:$C$13, COLUMN()-1)} -> 0.41111111 | H7: {=INDEX(Clean_Funnel_Data!$D$2:$D$13, COLUMN()-1) / INDEX(Clean_Funnel_Data!$C$2:$C$13, COLUMN()-1)} -> 0.32653061 | I7: {=INDEX(Clean_Funnel_Data!$D$2:$D$13, COLUMN()-1) / INDEX(Clean_Funnel_Data!$C$2:$C$13, COLUMN()-1)} -> 0.43 | ... M7: {=INDEX(Clean_Funnel_Data!$D$2:$D$13, COLUMN()-1) / INDEX(Clean_Funnel_Data!$C$2:$C$13, COLUMN()-1)} -> 0.35820896 | N7: =SUM(Clean_Funnel_Data!D2:D13) / SUM(Clean_Funnel_Data!C2:C13) -> 0.36348684
A8: Conv SQL → Opp | B8: {=INDEX(Clean_Funnel_Data!$F$2:$F$13, COLUMN()-1) / INDEX(Clean_Funnel_Data!$D$2:$D$13, COLUMN()-1)} -> 0.65517241 | C8: {=INDEX(Clean_Funnel_Data!$F$2:$F$13, COLUMN()-1) / INDEX(Clean_Funnel_Data!$D$2:$D$13, COLUMN()-1)} -> 0.5862069 | D8: {=INDEX(Clean_Funnel_Data!$F$2:$F$13, COLUMN()-1) / INDEX(Clean_Funnel_Data!$D$2:$D$13, COLUMN()-1)} -> 0.6875 | E8: {=INDEX(Clean_Funnel_Data!$F$2:$F$13, COLUMN()-1) / INDEX(Clean_Funnel_Data!$D$2:$D$13, COLUMN()-1)} -> 0.58333333 | F8: {=INDEX(Clean_Funnel_Data!$F$2:$F$13, COLUMN()-1) / INDEX(Clean_Funnel_Data!$D$2:$D$13, COLUMN()-1)} -> 0.47368421 | G8: {=INDEX(Clean_Funnel_Data!$F$2:$F$13, COLUMN()-1) / INDEX(Clean_Funnel_Data!$D$2:$D$13, COLUMN()-1)} -> 0.56756757 | H8: {=INDEX(Clean_Funnel_Data!$F$2:$F$13, COLUMN()-1) / INDEX(Clean_Funnel_Data!$D$2:$D$13, COLUMN()-1)} -> 0.625 | I8: {=INDEX(Clean_Funnel_Data!$F$2:$F$13, COLUMN()-1) / INDEX(Clean_Funnel_Data!$D$2:$D$13, COLUMN()-1)} -> 0.55813953 | ... M8: {=INDEX(Clean_Funnel_Data!$F$2:$F$13, COLUMN()-1) / INDEX(Clean_Funnel_Data!$D$2:$D$13, COLUMN()-1)} -> 0.5 | N8: =SUM(Clean_Funnel_Data!F2:F13) / SUM(Clean_Funnel_Data!D2:D13) -> 0.59728507
A9: Conv Opp → Won | B9: {=INDEX(Clean_Funnel_Data!$G$2:$G$13, COLUMN()-1) / INDEX(Clean_Funnel_Data!$F$2:$F$13, COLUMN()-1)} -> 0.21052632 | C9: {=INDEX(Clean_Funnel_Data!$G$2:$G$13, COLUMN()-1) / INDEX(Clean_Funnel_Data!$F$2:$F$13, COLUMN()-1)} -> 0.29411765 | D9: {=INDEX(Clean_Funnel_Data!$G$2:$G$13, COLUMN()-1) / INDEX(Clean_Funnel_Data!$F$2:$F$13, COLUMN()-1)} -> 0.27272727 | E9: {=INDEX(Clean_Funnel_Data!$G$2:$G$13, COLUMN()-1) / INDEX(Clean_Funnel_Data!$F$2:$F$13, COLUMN()-1)} -> 0.23809524 | F9: {=INDEX(Clean_Funnel_Data!$G$2:$G$13, COLUMN()-1) / INDEX(Clean_Funnel_Data!$F$2:$F$13, COLUMN()-1)} -> 0.27777778 | G9: {=INDEX(Clean_Funnel_Data!$G$2:$G$13, COLUMN()-1) / INDEX(Clean_Funnel_Data!$F$2:$F$13, COLUMN()-1)} -> 0.28571429 | H9: {=INDEX(Clean_Funnel_Data!$G$2:$G$13, COLUMN()-1) / INDEX(Clean_Funnel_Data!$F$2:$F$13, COLUMN()-1)} -> 0.35 | I9: {=INDEX(Clean_Funnel_Data!$G$2:$G$13, COLUMN()-1) / INDEX(Clean_Funnel_Data!$F$2:$F$13, COLUMN()-1)} -> 0.25 | ... M9: {=INDEX(Clean_Funnel_Data!$G$2:$G$13, COLUMN()-1) / INDEX(Clean_Funnel_Data!$F$2:$F$13, COLUMN()-1)} -> 0.33333333 | N9: =SUM(Clean_Funnel_Data!G2:G13) / SUM(Clean_Funnel_Data!F2:F13) -> 0.28030303
A12: Executive Commentary — GTM Funnel vs Plan (FY 2025)
A14: 1. Overall Performance:
A16: The GTM motion finished the year ahead of plan on revenue, delivering 101.5% attainment in New Bookings ARR ($2,665,000 vs $2,625,000 target; a +$40k beat).
A17: Sales qualification exceeded plan with 103.3% SQL attainment (442 actual vs 428 target), closing 74 deals against a 75-deal target (98.7% deal count attainment).
A18: 2. Funnel Dynamics & H2 Bottleneck:
A20: Top-of-funnel velocity expanded strongly in H2 (+34% MQLs in Q4 vs Q1), but downstream efficiency softened.
A21: Stage conversion from Opp -> Won compressed from a peak of 35.0% in July down to ~26% in September–October. This indicates account executive capacity constraints or looser late-stage qualification criteria as volume surged toward year-end.
A22: 3. Data Hygiene & Methodological Adjustments:
A24: June Duplicate Record: Identified and removed an identical duplicate export row for June-25 in the raw file. Failing to deduplicate would have distorted full-year bookings by +$190,000 and 6 phantom deals.
A25: March MQL Outlier (820 vs 88 Target): Identified an apparent clerical zero-typo. Normalizing to 82 MQLs restores MQL $\rightarrow$ SQL conversion to an on-trend 39.0% (vs a collapsed 3.9% under the unadjusted 820 leads). Both reported and normalized views are maintained for governance.
A26: August Missing Opportunities (NaN): Handled missing CRM stage logging by wrapping formulas in SI.ERROR to eliminate #¡DIV/0! errors. Imputed 24 opportunities based on the historical 60% SQL -> Opp baseline, yielding an annualized opportunity attainment of 99.6% (264 normalized vs 240 raw)

Sheet Clean_ARR_Data
A1: Customer_ID | B1: Customer_Name | C1: Product | D1: Snapshot_Month | E1: ARR_USD | F1: Customer_Name_Cleaned | G1: Product_Cleaned
A2: C008 | B2: Meridian Water Group | C2: analytics | D2: 45901 | E2: 24000 | F2: =+TRIM(B2) -> Meridian Water Group | G2: {=_xlfn.IFS( ISNUMBER(SEARCH("Core", C2)), "Core Platform", ISNUMBER(SEARCH("Analytics", C2)), "Analytics", ISNUMBER(SEARCH("Automation", C2)), "Automation" )} -> Analytics
A3: C026 | B3: Cobalt Networks | C3: Analytics | D3: 45992 | E3: 35000 | F3: =+TRIM(B3) -> Cobalt Networks | G3: {=_xlfn.IFS( ISNUMBER(SEARCH("Core", C3)), "Core Platform", ISNUMBER(SEARCH("Analytics", C3)), "Analytics", ISNUMBER(SEARCH("Automation", C3)), "Automation" )} -> Analytics
A4: C010 | B4: Pinecrest Property | C4: Automation | D4: 45931 | E4: 27000 | F4: =+TRIM(B4) -> Pinecrest Property | G4: {=_xlfn.IFS( ISNUMBER(SEARCH("Core", C4)), "Core Platform", ISNUMBER(SEARCH("Analytics", C4)), "Analytics", ISNUMBER(SEARCH("Automation", C4)), "Automation" )} -> Automation
A5: C024 | B5: Willowbrook Care | C5: Core | D5: 45870 | E5: 79000 | F5: =+TRIM(B5) -> Willowbrook Care | G5: {=_xlfn.IFS( ISNUMBER(SEARCH("Core", C5)), "Core Platform", ISNUMBER(SEARCH("Analytics", C5)), "Analytics", ISNUMBER(SEARCH("Automation", C5)), "Automation" )} -> Core Platform
A6: C009 | B6: Ironclad Security | C6: Analytics | D6: 45992 | E6: 45000 | F6: =+TRIM(B6) -> Ironclad Security | G6: {=_xlfn.IFS( ISNUMBER(SEARCH("Core", C6)), "Core Platform", ISNUMBER(SEARCH("Analytics", C6)), "Analytics", ISNUMBER(SEARCH("Automation", C6)), "Automation" )} -> Analytics
A7: C013 | B7: Granite State Mechanical | C7: Automation | D7: 45839 | E7: 10000 | F7: =+TRIM(B7) -> Granite State Mechanical | G7: {=_xlfn.IFS( ISNUMBER(SEARCH("Core", C7)), "Core Platform", ISNUMBER(SEARCH("Analytics", C7)), "Analytics", ISNUMBER(SEARCH("Automation", C7)), "Automation" )} -> Automation
A8: C005 | B8: Ridgeline HVAC | C8: Analytics | D8: 45870 | E8: 15000 | F8: =+TRIM(B8) -> Ridgeline HVAC | G8: {=_xlfn.IFS( ISNUMBER(SEARCH("Core", C8)), "Core Platform", ISNUMBER(SEARCH("Analytics", C8)), "Analytics", ISNUMBER(SEARCH("Automation", C8)), "Automation" )} -> Analytics
A9: C018 | B9: Kestrel Telecom | C9: Analytics | D9: 45748 | E9: 38000 | F9: =+TRIM(B9) -> Kestrel Telecom | G9: {=_xlfn.IFS( ISNUMBER(SEARCH("Core", C9)), "Core Platform", ISNUMBER(SEARCH("Analytics", C9)), "Analytics", ISNUMBER(SEARCH("Automation", C9)), "Automation" )} -> Analytics
A10: C002 | B10: Blue Harbor Logistics | C10: Core Platform | D10: 45962 | E10: 72000 | F10: =+TRIM(B10) -> Blue Harbor Logistics | G10: {=_xlfn.IFS( ISNUMBER(SEARCH("Core", C10)), "Core Platform", ISNUMBER(SEARCH("Analytics", C10)), "Analytics", ISNUMBER(SEARCH("Automation", C10)), "Automation" )} -> Core Platform
A11: C016 | B11: Atlas Elevator Co | C11: analytics | D11: 45717 | E11: 36000 | F11: =+TRIM(B11) -> Atlas Elevator Co | G11: {=_xlfn.IFS( ISNUMBER(SEARCH("Core", C11)), "Core Platform", ISNUMBER(SEARCH("Analytics", C11)), "Analytics", ISNUMBER(SEARCH("Automation", C11)), "Automation" )} -> Analytics
A12: C011 | B12: Summit Fire Protection | C12: Core Platform | D12: 45778 | E12: 77000 | F12: =+TRIM(B12) -> Summit Fire Protection | G12: {=_xlfn.IFS( ISNUMBER(SEARCH("Core", C12)), "Core Platform", ISNUMBER(SEARCH("Analytics", C12)), "Analytics", ISNUMBER(SEARCH("Automation", C12)), "Automation" )} -> Core Platform
A13: C009 | B13: Ironclad Security | C13: Automation | D13: 45627 | E13: 8000 | F13: =+TRIM(B13) -> Ironclad Security | G13: {=_xlfn.IFS( ISNUMBER(SEARCH("Core", C13)), "Core Platform", ISNUMBER(SEARCH("Analytics", C13)), "Analytics", ISNUMBER(SEARCH("Automation", C13)), "Automation" )} -> Automation
... A755: C007 | B755: Copperfield Electrical | C755: Core | D755: 45748 | E755: 62000 | F755: =+TRIM(B755) -> Copperfield Electrical | G755: {=_xlfn.IFS( ISNUMBER(SEARCH("Core", C755)), "Core Platform", ISNUMBER(SEARCH("Analytics", C755)), "Analytics", ISNUMBER(SEARCH("Automation", C755)), "Automation" )} -> Core Platform

Sheet Clean_Funnel_Data
A1: Month | B1: MQLs_Reported | C1: MQLs_Adjusted | D1: SQLs | E1: Opps_Reported | F1: Opps_Adjusted | G1: Closed Won | H1: New Bookings ARR
A2: Jan-25 | B2: 86 | C2: =IF(B2=820, 82, B2) -> 86 | D2: 29 | E2: 19 | F2: =IF(E2="", 24, E2) -> 19 | G2: 4 | H2: 160000
A3: Feb-25 | B3: 88 | C3: =IF(B3=820, 82, B3) -> 88 | D3: 29 | E3: 17 | F3: =IF(E3="", 24, E3) -> 17 | G3: 5 | H3: 164000
A4: Mar-25 | B4: 820 | C4: =IF(B4=820, 82, B4) -> 82 | D4: 32 | E4: 22 | F4: =IF(E4="", 24, E4) -> 22 | G4: 6 | H4: 206000
A5: Apr-25 | B5: 84 | C5: =IF(B5=820, 82, B5) -> 84 | D5: 36 | E5: 21 | F5: =IF(E5="", 24, E5) -> 21 | G5: 5 | H5: 150000
A6: May-25 | B6: 92 | C6: =IF(B6=820, 82, B6) -> 92 | D6: 38 | E6: 18 | F6: =IF(E6="", 24, E6) -> 18 | G6: 5 | H6: 210000
A7: Jun-25 | B7: 90 | C7: =IF(B7=820, 82, B7) -> 90 | D7: 37 | E7: 21 | F7: =IF(E7="", 24, E7) -> 21 | G7: 6 | H7: 190000
A8: Jul-25 | B8: 98 | C8: =IF(B8=820, 82, B8) -> 98 | D8: 32 | E8: 20 | F8: =IF(E8="", 24, E8) -> 20 | G8: 7 | H8: 270000
A9: Aug-25 | B9: 100 | C9: =IF(B9=820, 82, B9) -> 100 | D9: 43 | F9: =IF(E9="", 24, E9) -> 24 | G9: 6 | H9: 236000
A10: Sep-25 | B10: 114 | C10: =IF(B10=820, 82, B10) -> 114 | D10: 41 | E10: 27 | F10: =IF(E10="", 24, E10) -> 27 | G10: 7 | H10: 279000
A11: Oct-25 | B11: 130 | C11: =IF(B11=820, 82, B11) -> 130 | D11: 39 | E11: 26 | F11: =IF(E11="", 24, E11) -> 26 | G11: 7 | H11: 230000
A12: Nov-25 | B12: 118 | C12: =IF(B12=820, 82, B12) -> 118 | D12: 38 | E12: 25 | F12: =IF(E12="", 24, E12) -> 25 | G12: 8 | H12: 268000
A13: Dec-25 | B13: 134 | C13: =IF(B13=820, 82, B13) -> 134 | D13: 48 | E13: 24 | F13: =IF(E13="", 24, E13) -> 24 | G13: 8 | H13: 302000
A16: "Identified an exact duplicate export row for June-25 in the raw data. Deduplicated to 12 distinct reporting months; failure to deduplicate would have distorted full-year bookings by +$190,000 and 6 won deals."

Sheet Raw_Data
A1: Customer_ID | B1: Customer_Name | C1: Product | D1: Snapshot_Month | E1: ARR_USD
A2: C008 | B2: Meridian Water Group | C2: analytics | D2: 45901 | E2: 24000
A3: C026 | B3: Cobalt Networks | C3: Analytics | D3: 45992 | E3: 35000
A4: C010 | B4: Pinecrest Property | C4: Automation | D4: 45931 | E4: 27000
A5: C024 | B5: Willowbrook Care | C5: Core | D5: 45870 | E5: 79000
A6: C009 | B6: Ironclad Security | C6: Analytics | D6: 45992 | E6: 45000
A7: C013 | B7: Granite State Mechanical | C7: Automation | D7: 45839 | E7: 10000
A8: C005 | B8: Ridgeline HVAC | C8: Analytics | D8: 45870 | E8: 15000
A9: C018 | B9: Kestrel Telecom | C9: Analytics | D9: 45748 | E9: 38000
A10: C002 | B10: Blue Harbor Logistics | C10: Core Platform | D10: 45962 | E10: 72000
A11: C016 | B11: Atlas Elevator Co | C11: analytics | D11: 45717 | E11: 36000
A12: C011 | B12: Summit Fire Protection | C12: Core Platform | D12: 45778 | E12: 77000
A13: C009 | B13: Ironclad Security | C13: Automation | D13: 45627 | E13: 8000
... A22: C021 | B22: Delta Refrigeration | C22: Core | D22: 45870 | E22: 102000
A23: C016 | B23: Atlas Elevator Co | C23: Analytics | D23: 45962 | E23: 36000
A24: C008 | B24: Meridian Water Group | C24: Analytics | D24: 45962 | E24: 24000
A25: C013 | B25: Granite State Mechanical | C25: Automation | D25: 45748 | E25: 10000
A26: C016 | B26: Atlas Elevator Co | C26: Core | D26: 45839 | E26: 60000
A27: C014 | B27: Lakeside Energy | C27: Analytics | D27: 45901 | E27: 26000
A28: C014 | B28: Lakeside Energy | C28: Automation | D28: 45778 | E28: 11000
A29: C014 | B29: Lakeside Energy | C29: AUTOMATION | D29: 45717 | E29: 11000
A30: C012 | B30: Harborview Plumbing | C30: Core Platform | D30: 45658 | E30: 70000
A31: C004 | B31: Cedar Peak Utilities | C31: Automation | D31: 45717 | E31: 21000
A32: C020 | B32: Maple Grove Maintenance | C32: Analytics | D32: 45627 | E32: 31000
A33: C008 | B33: Meridian Water Group | C33: Core Platform | D33: 45870 | E33: 97000
A34: C012 | B34: Harborview Plumbing | C34: Core Platform | D34: 45748 | E34: 70000
A35: C026 | B35: Cobalt Networks | C35: Analytics | D35: 45962 | E35: 35000
... A97: C013 | B97: Granite State Mechanical | C97: Core Platform | D97: 45901 | E97: 79000
A98: C014 | B98: Lakeside Energy | C98: Core | D98: 45748 | E98: 112000
A99: C014 | B99: Lakeside Energy | C99: Core Platform | D99: 45931 | E99: 112000
A100: C002 | B100: Blue Harbor Logistics | C100: Core Platform | D100: 45870 | E100: 72000
A101: C013 | B101: Granite State Mechanical | C101: Core | D101: 45962 | E101: 90000
A102: C029 | B102: Silverline Rail | C102: Core | D102: 45870 | E102: 40000
A103: C015 | B103: Redwood Field Services | C103: Analytics | D103: 45992 | E103: 23000
A104: C029 | B104: Silverline Rail | C104: Automation | D104: 45992 | E104: 19000
A105: C005 | B105: Ridgeline HVAC | C105: Core | D105: 45778 | E105: 111000
A106: C008 | B106: Meridian Water Group | C106: Core Platform | D106: 45962 | E106: 97000
A107: C013 | B107: Granite State Mechanical | C107: Analytics | D107: 45931 | E107: 30000
A108: C014 | B108: Lakeside Energy | C108: Analytics | D108: 45658 | E108: 26000
A109: C018 | B109: Kestrel Telecom | C109: Analytics | D109: 45778 | E109: 38000
...

Sheet ARR_Data
A1: Customer_ID | B1: Customer_Name | C1: Product | D1: Snapshot_Month | E1: ARR_USD
A2: C008 | B2: Meridian Water Group | C2: analytics | D2: 45901 | E2: 24000
A3: C026 | B3: Cobalt Networks | C3: Analytics | D3: 45992 | E3: 35000
A4: C010 | B4: Pinecrest Property | C4: Automation | D4: 45931 | E4: 27000
A5: C024 | B5: Willowbrook Care | C5: Core | D5: 45870 | E5: 79000
A6: C009 | B6: Ironclad Security | C6: Analytics | D6: 45992 | E6: 45000
A7: C013 | B7: Granite State Mechanical | C7: Automation | D7: 45839 | E7: 10000
A8: C005 | B8: Ridgeline HVAC | C8: Analytics | D8: 45870 | E8: 15000
A9: C018 | B9: Kestrel Telecom | C9: Analytics | D9: 45748 | E9: 38000
A10: C002 | B10: Blue Harbor Logistics | C10: Core Platform | D10: 45962 | E10: 72000
A11: C016 | B11: Atlas Elevator Co | C11: analytics | D11: 45717 | E11: 36000
A12: C011 | B12: Summit Fire Protection | C12: Core Platform | D12: 45778 | E12: 77000
A13: C009 | B13: Ironclad Security | C13: Automation | D13: 45627 | E13: 8000
... A22: C021 | B22: Delta Refrigeration | C22: Core | D22: 45870 | E22: 102000
A23: C016 | B23: Atlas Elevator Co | C23: Analytics | D23: 45962 | E23: 36000
A24: C008 | B24: Meridian Water Group | C24: Analytics | D24: 45962 | E24: 24000
A25: C013 | B25: Granite State Mechanical | C25: Automation | D25: 45748 | E25: 10000
A26: C016 | B26: Atlas Elevator Co | C26: Core | D26: 45839 | E26: 60000
A27: C014 | B27: Lakeside Energy | C27: Analytics | D27: 45901 | E27: 26000
A28: C014 | B28: Lakeside Energy | C28: Automation | D28: 45778 | E28: 11000
A29: C014 | B29: Lakeside Energy | C29: AUTOMATION | D29: 45717 | E29: 11000
A30: C012 | B30: Harborview Plumbing | C30: Core Platform | D30: 45658 | E30: 70000
A31: C004 | B31: Cedar Peak Utilities | C31: Automation | D31: 45717 | E31: 21000
A32: C020 | B32: Maple Grove Maintenance | C32: Analytics | D32: 45627 | E32: 31000
A33: C008 | B33: Meridian Water Group | C33: Core Platform | D33: 45870 | E33: 97000
A34: C012 | B34: Harborview Plumbing | C34: Core Platform | D34: 45748 | E34: 70000
A35: C026 | B35: Cobalt Networks | C35: Analytics | D35: 45962 | E35: 35000
... A97: C013 | B97: Granite State Mechanical | C97: Core Platform | D97: 45901 | E97: 79000
A98: C014 | B98: Lakeside Energy | C98: Core | D98: 45748 | E98: 112000
A99: C014 | B99: Lakeside Energy | C99: Core Platform | D99: 45931 | E99: 112000
A100: C002 | B100: Blue Harbor Logistics | C100: Core Platform | D100: 45870 | E100: 72000
A101: C013 | B101: Granite State Mechanical | C101: Core | D101: 45962 | E101: 90000
A102: C029 | B102: Silverline Rail | C102: Core | D102: 45870 | E102: 40000
A103: C015 | B103: Redwood Field Services | C103: Analytics | D103: 45992 | E103: 23000
A104: C029 | B104: Silverline Rail | C104: Automation | D104: 45992 | E104: 19000
A105: C005 | B105: Ridgeline HVAC | C105: Core | D105: 45778 | E105: 111000
A106: C008 | B106: Meridian Water Group | C106: Core Platform | D106: 45962 | E106: 97000
A107: C013 | B107: Granite State Mechanical | C107: Analytics | D107: 45931 | E107: 30000
A108: C014 | B108: Lakeside Energy | C108: Analytics | D108: 45658 | E108: 26000
A109: C018 | B109: Kestrel Telecom | C109: Analytics | D109: 45778 | E109: 38000
...

Sheet Targets
A1: Period | B1: MQL | C1: SQL | D1: Opportunities | E1: Closed Won | F1: New Bookings ARR
A2: 2025-01 | B2: 80 | C2: 28 | D2: 17 | E2: 5 | F2: 175000
A3: 2025-02 | B3: 84 | C3: 29 | D3: 18 | E3: 5 | F3: 175000
A4: 2025-03 | B4: 88 | C4: 31 | D4: 19 | E4: 5 | F4: 175000
A5: 2025-04 | B5: 92 | C5: 32 | D5: 20 | E5: 6 | F5: 210000
A6: 2025-05 | B6: 96 | C6: 34 | D6: 21 | E6: 6 | F6: 210000
A7: 2025-06 | B7: 100 | C7: 35 | D7: 22 | E7: 6 | F7: 210000
A8: 2025-07 | B8: 104 | C8: 36 | D8: 22 | E8: 6 | F8: 210000
A9: 2025-08 | B9: 108 | C9: 38 | D9: 24 | E9: 7 | F9: 245000
A10: 2025-09 | B10: 112 | C10: 39 | D10: 24 | E10: 7 | F10: 245000
A11: 2025-10 | B11: 116 | C11: 41 | D11: 25 | E11: 7 | F11: 245000
A12: 2025-11 | B12: 120 | C12: 42 | D12: 26 | E12: 7 | F12: 245000
A13: 2025-12 | B13: 124 | C13: 43 | D13: 27 | E13: 8 | F13: 280000

Sheet Funnel_Actuals
A1: Month | B1: MQLs | C1: SQLs | D1: Opps Created | E1: Closed Won | F1: New Bookings ARR
A2: Jan-25 | B2: 86 | C2: 29 | D2: 19 | E2: 4 | F2: 160000
A3: Feb-25 | B3: 88 | C3: 29 | D3: 17 | E3: 5 | F3: 164000
A4: Mar-25 | B4: 820 | C4: 32 | D4: 22 | E4: 6 | F4: 206000
A5: Apr-25 | B5: 84 | C5: 36 | D5: 21 | E5: 5 | F5: 150000
A6: May-25 | B6: 92 | C6: 38 | D6: 18 | E6: 5 | F6: 210000
A7: Jun-25 | B7: 90 | C7: 37 | D7: 21 | E7: 6 | F7: 190000
A8: Jun-25 | B8: 90 | C8: 37 | D8: 21 | E8: 6 | F8: 190000
A9: Jul-25 | B9: 98 | C9: 32 | D9: 20 | E9: 7 | F9: 270000
A10: Aug-25 | B10: 100 | C10: 43 | E10: 6 | F10: 236000
A11: Sep-25 | B11: 114 | C11: 41 | D11: 27 | E11: 7 | F11: 279000
A12: Oct-25 | B12: 130 | C12: 39 | D12: 26 | E12: 7 | F12: 230000
A13: Nov-25 | B13: 118 | C13: 38 | D13: 25 | E13: 8 | F13: 268000
A14: Dec-25 | B14: 134 | C14: 48 | D14: 24 | E14: 8 | F14: 302000
